<?xml version="1.0" ?>
<!-- =================================================================================== -->
<!-- |    This document was autogenerated by xacro from mishanya.xacro                 | -->
<!-- |    EDITING THIS FILE BY HAND IS NOT RECOMMENDED                                 | -->
<!-- =================================================================================== -->
<robot name="mishanya">
  <!-- kernel property -->
  <!-- kernel property -->
  <!-- inertial macros -->
  <!-- inertial macros -->
  <!-- base property -->
  <!-- base property -->
  <!-- inertial macros -->
  <!-- inertial macros -->
  <link name="base_link">
    <collision name="collision_chassis">
      <origin rpy="0 0 0" xyz="0 0 0"/>
      <geometry>
        <cylinder length="0.21" radius="0.4"/>
      </geometry>
    </collision>
    <visual>
      <origin rpy="0 0 0" xyz="0 0 0"/>
      <geometry>
        <cylinder length="0.21" radius="0.4"/>
      </geometry>
    </visual>
    <inertial>
      <origin rpy="0 0 0" xyz="0 0 0"/>
      <mass value="5"/>
      <inertia ixx="0.218375" ixy="0.0" ixz="0.0" iyy="0.218375" iyz="0.0" izz="0.4"/>
    </inertial>
  </link>
  <!-- in kg-->
  <link name="base_footprint">
    <visual>
      <origin rpy="0 0 0" xyz="0 0 0"/>
      <geometry>
        <box size="0.001 0.001 0.001"/>
      </geometry>
    </visual>
  </link>
  <joint name="base_footprint_joint" type="fixed">
    <origin rpy="0 0 0" xyz="0 0 0.16849999999999998"/>
    <parent link="base_footprint"/>
    <child link="base_link"/>
  </joint>
  <link name="kernel">
    <inertial>
      <origin rpy="0 0 0" xyz="0 0 0"/>
      <mass value="0.5"/>
      <inertia ixx="0.011816666666666668" ixy="0.0" ixz="0.0" iyy="0.011816666666666668" iyz="0.0" izz="0.000225"/>
    </inertial>
    <collision name="link_kernel_collision">
      <origin rpy="0 0 0" xyz="0 0 0.265"/>
      <geometry>
        <cylinder length="0.53" radius="0.03"/>
      </geometry>
    </collision>
    <visual name="kernel_visual">
      <origin rpy="0 0 0" xyz="0 0 0.265"/>
      <geometry>
        <cylinder length="0.53" radius="0.03"/>
      </geometry>
    </visual>
  </link>
  <joint name="joint_kernel" type="fixed">
    <origin rpy="0 0 0" xyz="0 0 0.105"/>
    <child link="kernel"/>
    <parent link="base_link"/>
    <axis rpy="0 0 0" xyz="0 0 0.105"/>
    <limit effort="0" velocity="0"/>
  </joint>
  <joint name="front_wheel_joint" type="continuous">
    <parent link="base_link"/>
    <child link="front_wheel_link"/>
    <origin rpy="0 0 1.5707963267948966" xyz="0.4 0 -0.105"/>
    <axis rpy="0 0 0" xyz="0 1 0"/>
    <limit effort="100" velocity="100"/>
    <joint_properties damping="0.0" friction="0.0"/>
  </joint>
  <link name="front_wheel_link">
    <visual>
      <origin rpy="0 0 0" xyz="0 0 0"/>
      <geometry>
        <mesh filename="package://summit_description/meshes/wheels/omni_wheel_2.dae" scale="0.5 0.5 0.5"/>
      </geometry>
    </visual>
    <collision>
      <origin rpy="1.5707963267948966 0 0" xyz="0 0 0"/>
      <geometry>
        <cylinder length="0.00435" radius="0.0635"/>
      </geometry>
    </collision>
    <solid_cylinder_inertial h="0.00435" mass="3.25" r="0.0635">
      <origin rpy="0 0 0" xyz="0 0 0"/>
    </solid_cylinder_inertial>
  </link>
  <!-- Transmission is important to link the joints and the controller (see summit_xl_control/config/summit_xl_control.yaml)-->
  <transmission name="front_wheel_joint_trans">
    <type>transmission_interface/SimpleTransmission</type>
    <joint name="front_wheel_joint">
      <hardwareInterface>hardware_interface/VelocityJointInterface</hardwareInterface>
    </joint>
    <actuator name="front_wheel_joint_motor">
      <mechanicalReduction>1</mechanicalReduction>
    </actuator>
  </transmission>
  <joint name="back_left_wheel_joint" type="continuous">
    <parent link="base_link"/>
    <child link="back_left_wheel_link"/>
    <origin rpy="0 0 0.7853981633974483" xyz="-0.282842712474619 0.282842712474619 -0.105"/>
    <axis rpy="0 0 0" xyz="0 1 0"/>
    <limit effort="100" velocity="100"/>
    <joint_properties damping="0.0" friction="0.0"/>
  </joint>
  <link name="back_left_wheel_link">
    <visual>
      <origin rpy="0 0 0" xyz="0 0 0"/>
      <geometry>
        <mesh filename="package://summit_description/meshes/wheels/omni_wheel_2.dae" scale="0.5 0.5 0.5"/>
      </geometry>
    </visual>
    <collision>
      <origin rpy="1.5707963267948966 0 0" xyz="0 0 0"/>
      <geometry>
        <cylinder length="0.00435" radius="0.0635"/>
      </geometry>
    </collision>
    <solid_cylinder_inertial h="0.00435" mass="3.25" r="0.0635">
      <origin rpy="0 0 0" xyz="0 0 0"/>
    </solid_cylinder_inertial>
  </link>
  <!-- Transmission is important to link the joints and the controller (see summit_xl_control/config/summit_xl_control.yaml)-->
  <transmission name="back_left_wheel_joint_trans">
    <type>transmission_interface/SimpleTransmission</type>
    <joint name="back_left_wheel_joint">
      <hardwareInterface>hardware_interface/VelocityJointInterface</hardwareInterface>
    </joint>
    <actuator name="back_left_wheel_joint_motor">
      <mechanicalReduction>1</mechanicalReduction>
    </actuator>
  </transmission>
  <joint name="back_right_wheel_joint" type="continuous">
    <parent link="base_link"/>
    <child link="back_right_wheel_link"/>
    <origin rpy="0 0 -0.7853981633974483" xyz="-0.282842712474619 -0.282842712474619  -0.105"/>
    <axis rpy="0 0 0" xyz="0 1 0"/>
    <limit effort="100" velocity="100"/>
    <joint_properties damping="0.0" friction="0.0"/>
  </joint>
  <link name="back_right_wheel_link">
    <visual>
      <origin rpy="0 0 0" xyz="0 0 0"/>
      <geometry>
        <mesh filename="package://summit_description/meshes/wheels/omni_wheel_2.dae" scale="0.5 0.5 0.5"/>
      </geometry>
    </visual>
    <collision>
      <origin rpy="1.5707963267948966 0 0" xyz="0 0 0"/>
      <geometry>
        <cylinder length="0.00435" radius="0.0635"/>
      </geometry>
    </collision>
    <solid_cylinder_inertial h="0.00435" mass="3.25" r="0.0635">
      <origin rpy="0 0 0" xyz="0 0 0"/>
    </solid_cylinder_inertial>
  </link>
  <!-- Transmission is important to link the joints and the controller (see summit_xl_control/config/summit_xl_control.yaml)-->
  <transmission name="back_right_wheel_joint_trans">
    <type>transmission_interface/SimpleTransmission</type>
    <joint name="back_right_wheel_joint">
      <hardwareInterface>hardware_interface/VelocityJointInterface</hardwareInterface>
    </joint>
    <actuator name="back_right_wheel_joint_motor">
      <mechanicalReduction>1</mechanicalReduction>
    </actuator>
  </transmission>
</robot>
